Workbook

Sheet EMPLOYEE MASTER DATA
A1: EMPLOYEE MASTER DATA
A3: Emp No | B3: Employee Name | C3: Location | D3: Department | E3: Designation | F3: Basic Salary
A4: EMP001 | B4: Vijay V | C4: Hyderabad | D4: Production | E4: Production Executive | F4: 29000
A5: EMP002 | B5: Sathish V | C5: Hyderabad | D5: Production | E5: Shift Incharge | F5: 46500
A6: EMP003 | B6: Aravind B | C6: Chennai | D6: Business Development | E6: Senior Business Development Executive | F6: 44500
A7: EMP004 | B7: Ramesh Kumar | C7: Bengaluru | D7: Front Office | E7: Receptionist | F7: 20500
A8: EMP005 | B8: Naveen Kumar | C8: Coimbatore | D8: Front Office | E8: Front Office Executive | F8: 29000
A9: EMP006 | B9: Karthik T | C9: Bengaluru | D9: Admin | E9: Admin Manager | F9: 53500
A10: EMP007 | B10: Arun B | C10: Kochi | D10: Admin | E10: Office Coordinator | F10: 25500
A11: EMP008 | B11: Sathish G | C11: Kochi | D11: Accounts | E11: Accountant | F11: 27500
A12: EMP009 | B12: Yuvaraj Babu | C12: Noida | D12: Sales | E12: Senior Sales Executive | F12: 43500
A13: EMP010 | B13: Sanjay G | C13: Delhi | D13: Procurement | E13: Buyer | F13: 45000
A14: EMP011 | B14: Vijay T | C14: Chennai | D14: Accounts | E14: Finance Executive | F14: 36000
A15: EMP012 | B15: Mohan M | C15: Chennai | D15: Admin | E15: Office Administrator | F15: 28000
... A303: EMP300 | B303: Ganesh Narayanan | C303: Hyderabad | D303: Maintenance | E303: Maintenance Supervisor | F303: 42000

Sheet DAY ATTENDANCE
A1: DAY ATTENDANCE - 01/02/2026
A2: Employee Number | B2: Name | C2: Location | D2: Department | E2: Designation | F2: In Time | G2: Out Time | H2: Work Hours | I2: Status | J2: Late | K2: Remarks
A3: {=_xlfn.SORTBY('EMPLOYEE MASTER DATA'!A4:E303,'EMPLOYEE MASTER DATA'!D4:D303,1)} -> EMP008 | B3: Sathish G | C3: Kochi | D3: Accounts | E3: Accountant | F3: 0.38888889 | G3: 0.78888889 | H3: =IF(OR(F3="",G3=""),0,G3-F3-TIME(1,0,0)) -> 0.35833333 | I3: =IF(F3="","Absent",IF(F3>TIME(9,30,0),"Late","Present")) -> Present | J3: =IF(F3="","",IF(F3<=TIME(9,30,0),0,F3-TIME(9,30,0))) -> 0 | K3: =IF(AND(F3<>"",G3=""),"On Duty","")
A4: EMP011 | B4: Vijay T | C4: Chennai | D4: Accounts | E4: Finance Executive | F4: 0.38680556 | G4: 0.78263889 | H4: =IF(OR(F4="",G4=""),0,G4-F4-TIME(1,0,0)) -> 0.35416667 | I4: =IF(F4="","Absent",IF(F4>TIME(9,30,0),"Late","Present")) -> Present | J4: =IF(F4="","",IF(F4<=TIME(9,30,0),0,F4-TIME(9,30,0))) -> 0 | K4: =IF(AND(F4<>"",G4=""),"On Duty","")
A5: EMP013 | B5: Madhan Selvam | C5: Mumbai | D5: Accounts | E5: Senior Accountant | F5: 0.40625 | H5: =IF(OR(F5="",G5=""),0,G5-F5-TIME(1,0,0)) -> 0 | I5: =IF(F5="","Absent",IF(F5>TIME(9,30,0),"Late","Present")) -> Late | J5: =IF(F5="","",IF(F5<=TIME(9,30,0),0,F5-TIME(9,30,0))) -> 0.010416667 | K5: =IF(AND(F5<>"",G5=""),"On Duty","") -> On Duty
A6: EMP029 | B6: Harish N | C6: Pune | D6: Accounts | E6: Accountant | F6: 0.38680556 | G6: 0.78125 | H6: =IF(OR(F6="",G6=""),0,G6-F6-TIME(1,0,0)) -> 0.35277778 | I6: =IF(F6="","Absent",IF(F6>TIME(9,30,0),"Late","Present")) -> Present | J6: =IF(F6="","",IF(F6<=TIME(9,30,0),0,F6-TIME(9,30,0))) -> 0 | K6: =IF(AND(F6<>"",G6=""),"On Duty","")
A7: EMP042 | B7: Prakash S | C7: Coimbatore | D7: Accounts | E7: Accounts Manager | F7: 0.39305556 | H7: =IF(OR(F7="",G7=""),0,G7-F7-TIME(1,0,0)) -> 0 | I7: =IF(F7="","Absent",IF(F7>TIME(9,30,0),"Late","Present")) -> Present | J7: =IF(F7="","",IF(F7<=TIME(9,30,0),0,F7-TIME(9,30,0))) -> 0 | K7: =IF(AND(F7<>"",G7=""),"On Duty","") -> On Duty
A8: EMP050 | B8: Manoj P | C8: Chennai | D8: Accounts | E8: Senior Accountant | F8: 0.39444444 | G8: 0.78472222 | H8: =IF(OR(F8="",G8=""),0,G8-F8-TIME(1,0,0)) -> 0.34861111 | I8: =IF(F8="","Absent",IF(F8>TIME(9,30,0),"Late","Present")) -> Present | J8: =IF(F8="","",IF(F8<=TIME(9,30,0),0,F8-TIME(9,30,0))) -> 0 | K8: =IF(AND(F8<>"",G8=""),"On Duty","")
A9: EMP067 | B9: Vignesh Raja | C9: Mumbai | D9: Accounts | E9: Finance Executive | F9: 0.38819444 | H9: =IF(OR(F9="",G9=""),0,G9-F9-TIME(1,0,0)) -> 0 | I9: =IF(F9="","Absent",IF(F9>TIME(9,30,0),"Late","Present")) -> Present | J9: =IF(F9="","",IF(F9<=TIME(9,30,0),0,F9-TIME(9,30,0))) -> 0 | K9: =IF(AND(F9<>"",G9=""),"On Duty","") -> On Duty
A10: EMP069 | B10: Yogesh M | C10: Bengaluru | D10: Accounts | E10: Accounts Manager | F10: 0.40416667 | G10: 0.77708333 | H10: =IF(OR(F10="",G10=""),0,G10-F10-TIME(1,0,0)) -> 0.33125 | I10: =IF(F10="","Absent",IF(F10>TIME(9,30,0),"Late","Present")) -> Late | J10: =IF(F10="","",IF(F10<=TIME(9,30,0),0,F10-TIME(9,30,0))) -> 0.0083333333 | K10: =IF(AND(F10<>"",G10=""),"On Duty","")
A11: EMP070 | B11: Rahul Krishnan | C11: Chennai | D11: Accounts | E11: Accounts Manager | F11: 0.40208333 | H11: =IF(OR(F11="",G11=""),0,G11-F11-TIME(1,0,0)) -> 0 | I11: =IF(F11="","Absent",IF(F11>TIME(9,30,0),"Late","Present")) -> Late | J11: =IF(F11="","",IF(F11<=TIME(9,30,0),0,F11-TIME(9,30,0))) -> 0.00625 | K11: =IF(AND(F11<>"",G11=""),"On Duty","") -> On Duty
A12: EMP072 | B12: Sanjay S | C12: Bengaluru | D12: Accounts | E12: Finance Executive | F12: 0.38263889 | G12: 0.77916667 | H12: =IF(OR(F12="",G12=""),0,G12-F12-TIME(1,0,0)) -> 0.35486111 | I12: =IF(F12="","Absent",IF(F12>TIME(9,30,0),"Late","Present")) -> Present | J12: =IF(F12="","",IF(F12<=TIME(9,30,0),0,F12-TIME(9,30,0))) -> 0 | K12: =IF(AND(F12<>"",G12=""),"On Duty","")
A13: EMP076 | B13: Prakash T | C13: Pune | D13: Accounts | E13: Accountant | F13: 0.40069444 | G13: 0.77083333 | H13: =IF(OR(F13="",G13=""),0,G13-F13-TIME(1,0,0)) -> 0.32847222 | I13: =IF(F13="","Absent",IF(F13>TIME(9,30,0),"Late","Present")) -> Late | J13: =IF(F13="","",IF(F13<=TIME(9,30,0),0,F13-TIME(9,30,0))) -> 0.0048611111 | K13: =IF(AND(F13<>"",G13=""),"On Duty","")
A14: EMP093 | B14: Suresh Raj | C14: Mumbai | D14: Accounts | E14: Accounts Manager | H14: =IF(OR(F14="",G14=""),0,G14-F14-TIME(1,0,0)) -> 0 | I14: =IF(F14="","Absent",IF(F14>TIME(9,30,0),"Late","Present")) -> Absent | J14: =IF(F14="","",IF(F14<=TIME(9,30,0),0,F14-TIME(9,30,0))) | K14: =IF(AND(F14<>"",G14=""),"On Duty","")
A15: EMP099 | B15: Yuvaraj N | C15: Kochi | D15: Accounts | E15: Accounts Manager | F15: 0.38402778 | G15: 0.77569444 | H15: =IF(OR(F15="",G15=""),0,G15-F15-TIME(1,0,0)) -> 0.35 | I15: =IF(F15="","Absent",IF(F15>TIME(9,30,0),"Late","Present")) -> Present | J15: =IF(F15="","",IF(F15<=TIME(9,30,0),0,F15-TIME(9,30,0))) -> 0 | K15: =IF(AND(F15<>"",G15=""),"On Duty","")
A16: EMP105 | B16: Nithin V | C16: Mumbai | D16: Accounts | E16: Senior Accountant | F16: 0.38333333 | G16: 0.77847222 | H16: =IF(OR(F16="",G16=""),0,G16-F16-TIME(1,0,0)) -> 0.35347222 | I16: =IF(F16="","Absent",IF(F16>TIME(9,30,0),"Late","Present")) -> Present | J16: =IF(F16="","",IF(F16<=TIME(9,30,0),0,F16-TIME(9,30,0))) -> 0 | K16: =IF(AND(F16<>"",G16=""),"On Duty","")
A17: EMP118 | B17: Prakash Raj | C17: Delhi | D17: Accounts | E17: Senior Accountant | F17: 0.38680556 | G17: 0.78958333 | H17: =IF(OR(F17="",G17=""),0,G17-F17-TIME(1,0,0)) -> 0.36111111 | I17: =IF(F17="","Absent",IF(F17>TIME(9,30,0),"Late","Present")) -> Present | J17: =IF(F17="","",IF(F17<=TIME(9,30,0),0,F17-TIME(9,30,0))) -> 0 | K17: =IF(AND(F17<>"",G17=""),"On Duty","")
A18: EMP127 | B18: Dinesh Krishnan | C18: Hyderabad | D18: Accounts | E18: Accounts Manager | F18: 0.375 | G18: 0.77708333 | H18: =IF(OR(F18="",G18=""),0,G18-F18-TIME(1,0,0)) -> 0.36041667 | I18: =IF(F18="","Absent",IF(F18>TIME(9,30,0),"Late","Present")) -> Present | J18: =IF(F18="","",IF(F18<=TIME(9,30,0),0,F18-TIME(9,30,0))) -> 0 | K18: =IF(AND(F18<>"",G18=""),"On Duty","")
A19: EMP129 | B19: Dinesh Selvam | C19: Hyderabad | D19: Accounts | E19: Finance Executive | F19: 0.39305556 | G19: 0.78333333 | H19: =IF(OR(F19="",G19=""),0,G19-F19-TIME(1,0,0)) -> 0.34861111 | I19: =IF(F19="","Absent",IF(F19>TIME(9,30,0),"Late","Present")) -> Present | J19: =IF(F19="","",IF(F19<=TIME(9,30,0),0,F19-TIME(9,30,0))) -> 0 | K19: =IF(AND(F19<>"",G19=""),"On Duty","")
A20: EMP157 | B20: Yogesh S | C20: Coimbatore | D20: Accounts | E20: Accountant | F20: 0.39513889 | G20: 0.78194444 | H20: =IF(OR(F20="",G20=""),0,G20-F20-TIME(1,0,0)) -> 0.34513889 | I20: =IF(F20="","Absent",IF(F20>TIME(9,30,0),"Late","Present")) -> Present | J20: =IF(F20="","",IF(F20<=TIME(9,30,0),0,F20-TIME(9,30,0))) -> 0 | K20: =IF(AND(F20<>"",G20=""),"On Duty","")
A21: EMP158 | B21: Karthik P | C21: Ahmedabad | D21: Accounts | E21: Accounts Manager | F21: 0.4 | G21: 0.78333333 | H21: =IF(OR(F21="",G21=""),0,G21-F21-TIME(1,0,0)) -> 0.34166667 | I21: =IF(F21="","Absent",IF(F21>TIME(9,30,0),"Late","Present")) -> Late | J21: =IF(F21="","",IF(F21<=TIME(9,30,0),0,F21-TIME(9,30,0))) -> 0.0041666667 | K21: =IF(AND(F21<>"",G21=""),"On Duty","")
A22: EMP162 | B22: Ramesh G | C22: Chennai | D22: Accounts | E22: Accounts Executive | F22: 0.39722222 | H22: =IF(OR(F22="",G22=""),0,G22-F22-TIME(1,0,0)) -> 0 | I22: =IF(F22="","Absent",IF(F22>TIME(9,30,0),"Late","Present")) -> Late | J22: =IF(F22="","",IF(F22<=TIME(9,30,0),0,F22-TIME(9,30,0))) -> 0.0013888889 | K22: =IF(AND(F22<>"",G22=""),"On Duty","") -> On Duty
A23: EMP166 | B23: Dinesh B | C23: Pune | D23: Accounts | E23: Accounts Manager | F23: 0.39444444 | G23: 0.77361111 | H23: =IF(OR(F23="",G23=""),0,G23-F23-TIME(1,0,0)) -> 0.3375 | I23: =IF(F23="","Absent",IF(F23>TIME(9,30,0),"Late","Present")) -> Present | J23: =IF(F23="","",IF(F23<=TIME(9,30,0),0,F23-TIME(9,30,0))) -> 0 | K23: =IF(AND(F23<>"",G23=""),"On Duty","")
A24: EMP181 | B24: Manoj Narayanan | C24: Ahmedabad | D24: Accounts | E24: Senior Accountant | F24: 0.40138889 | G24: 0.7875 | H24: =IF(OR(F24="",G24=""),0,G24-F24-TIME(1,0,0)) -> 0.34444444 | I24: =IF(F24="","Absent",IF(F24>TIME(9,30,0),"Late","Present")) -> Late | J24: =IF(F24="","",IF(F24<=TIME(9,30,0),0,F24-TIME(9,30,0))) -> 0.0055555556 | K24: =IF(AND(F24<>"",G24=""),"On Duty","")
A25: EMP205 | B25: Manoj M | C25: Hyderabad | D25: Accounts | E25: Finance Executive | F25: 0.37916667 | G25: 0.77291667 | H25: =IF(OR(F25="",G25=""),0,G25-F25-TIME(1,0,0)) -> 0.35208333 | I25: =IF(F25="","Absent",IF(F25>TIME(9,30,0),"Late","Present")) -> Present | J25: =IF(F25="","",IF(F25<=TIME(9,30,0),0,F25-TIME(9,30,0))) -> 0 | K25: =IF(AND(F25<>"",G25=""),"On Duty","")
A26: EMP206 | B26: Naveen V | C26: Coimbatore | D26: Accounts | E26: Accounts Executive | F26: 0.39166667 | G26: 0.77152778 | H26: =IF(OR(F26="",G26=""),0,G26-F26-TIME(1,0,0)) -> 0.33819444 | I26: =IF(F26="","Absent",IF(F26>TIME(9,30,0),"Late","Present")) -> Present | J26: =IF(F26="","",IF(F26<=TIME(9,30,0),0,F26-TIME(9,30,0))) -> 0 | K26: =IF(AND(F26<>"",G26=""),"On Duty","")
A27: EMP208 | B27: Ganesh Krishnan | C27: Coimbatore | D27: Accounts | E27: Senior Accountant | F27: 0.38680556 | G27: 0.77430556 | H27: =IF(OR(F27="",G27=""),0,G27-F27-TIME(1,0,0)) -> 0.34583333 | I27: =IF(F27="","Absent",IF(F27>TIME(9,30,0),"Late","Present")) -> Present | J27: =IF(F27="","",IF(F27<=TIME(9,30,0),0,F27-TIME(9,30,0))) -> 0 | K27: =IF(AND(F27<>"",G27=""),"On Duty","")
A28: EMP218 | B28: Rahul V | C28: Noida | D28: Accounts | E28: Senior Accountant | F28: 0.40069444 | G28: 0.77986111 | H28: =IF(OR(F28="",G28=""),0,G28-F28-TIME(1,0,0)) -> 0.3375 | I28: =IF(F28="","Absent",IF(F28>TIME(9,30,0),"Late","Present")) -> Late | J28: =IF(F28="","",IF(F28<=TIME(9,30,0),0,F28-TIME(9,30,0))) -> 0.0048611111 | K28: =IF(AND(F28<>"",G28=""),"On Duty","")
A29: EMP229 | B29: Mohan Babu | C29: Noida | D29: Accounts | E29: Accountant | F29: 0.38541667 | G29: 0.775 | H29: =IF(OR(F29="",G29=""),0,G29-F29-TIME(1,0,0)) -> 0.34791667 | I29: =IF(F29="","Absent",IF(F29>TIME(9,30,0),"Late","Present")) -> Present | J29: =IF(F29="","",IF(F29<=TIME(9,30,0),0,F29-TIME(9,30,0))) -> 0 | K29: =IF(AND(F29<>"",G29=""),"On Duty","")
A30: EMP263 | B30: Bharath Prasad | C30: Delhi | D30: Accounts | E30: Accounts Executive | F30: 0.37916667 | G30: 0.78402778 | H30: =IF(OR(F30="",G30=""),0,G30-F30-TIME(1,0,0)) -> 0.36319444 | I30: =IF(F30="","Absent",IF(F30>TIME(9,30,0),"Late","Present")) -> Present | J30: =IF(F30="","",IF(F30<=TIME(9,30,0),0,F30-TIME(9,30,0))) -> 0 | K30: =IF(AND(F30<>"",G30=""),"On Duty","")
A31: EMP272 | B31: Bharath P | C31: Delhi | D31: Accounts | E31: Accountant | F31: 0.4 | H31: =IF(OR(F31="",G31=""),0,G31-F31-TIME(1,0,0)) -> 0 | I31: =IF(F31="","Absent",IF(F31>TIME(9,30,0),"Late","Present")) -> Late | J31: =IF(F31="","",IF(F31<=TIME(9,30,0),0,F31-TIME(9,30,0))) -> 0.0041666667 | K31: =IF(AND(F31<>"",G31=""),"On Duty","") -> On Duty
A32: EMP275 | B32: Ashwin Raja | C32: Kochi | D32: Accounts | E32: Accounts Executive | F32: 0.4 | G32: 0.77361111 | H32: =IF(OR(F32="",G32=""),0,G32-F32-TIME(1,0,0)) -> 0.33194444 | I32: =IF(F32="","Absent",IF(F32>TIME(9,30,0),"Late","Present")) -> Late | J32: =IF(F32="","",IF(F32<=TIME(9,30,0),0,F32-TIME(9,30,0))) -> 0.0041666667 | K32: =IF(AND(F32<>"",G32=""),"On Duty","")
A33: EMP291 | B33: Bharath N | C33: Chennai | D33: Accounts | E33: Senior Accountant | F33: 0.38125 | H33: =IF(OR(F33="",G33=""),0,G33-F33-TIME(1,0,0)) -> 0 | I33: =IF(F33="","Absent",IF(F33>TIME(9,30,0),"Late","Present")) -> Present | J33: =IF(F33="","",IF(F33<=TIME(9,30,0),0,F33-TIME(9,30,0))) -> 0 | K33: =IF(AND(F33<>"",G33=""),"On Duty","") -> On Duty
A34: EMP299 | B34: Ashwin B | C34: Ahmedabad | D34: Accounts | E34: Accountant | F34: 0.3875 | G34: 0.7875 | H34: =IF(OR(F34="",G34=""),0,G34-F34-TIME(1,0,0)) -> 0.35833333 | I34: =IF(F34="","Absent",IF(F34>TIME(9,30,0),"Late","Present")) -> Present | J34: =IF(F34="","",IF(F34<=TIME(9,30,0),0,F34-TIME(9,30,0))) -> 0 | K34: =IF(AND(F34<>"",G34=""),"On Duty","")
A35: EMP006 | B35: Karthik T | C35: Bengaluru | D35: Admin | E35: Admin Manager | F35: 0.38472222 | G35: 0.79097222 | H35: =IF(OR(F35="",G35=""),0,G35-F35-TIME(1,0,0)) -> 0.36458333 | I35: =IF(F35="","Absent",IF(F35>TIME(9,30,0),"Late","Present")) -> Present | J35: =IF(F35="","",IF(F35<=TIME(9,30,0),0,F35-TIME(9,30,0))) -> 0 | K35: =IF(AND(F35<>"",G35=""),"On Duty","")
A36: EMP007 | B36: Arun B | C36: Kochi | D36: Admin | E36: Office Coordinator | F36: 0.40208333 | G36: 0.77361111 | H36: =IF(OR(F36="",G36=""),0,G36-F36-TIME(1,0,0)) -> 0.32986111 | I36: =IF(F36="","Absent",IF(F36>TIME(9,30,0),"Late","Present")) -> Late | J36: =IF(F36="","",IF(F36<=TIME(9,30,0),0,F36-TIME(9,30,0))) -> 0.00625 | K36: =IF(AND(F36<>"",G36=""),"On Duty","")
A37: EMP012 | B37: Mohan M | C37: Chennai | D37: Admin | E37: Office Administrator | F37: 0.4 | G37: 0.77361111 | H37: =IF(OR(F37="",G37=""),0,G37-F37-TIME(1,0,0)) -> 0.33194444 | I37: =IF(F37="","Absent",IF(F37>TIME(9,30,0),"Late","Present")) -> Late | J37: =IF(F37="","",IF(F37<=TIME(9,30,0),0,F37-TIME(9,30,0))) -> 0.0041666667 | K37: =IF(AND(F37<>"",G37=""),"On Duty","")
A38: EMP015 | B38: Yogesh Babu | C38: Bengaluru | D38: Admin | E38: Office Administrator | F38: 0.39861111 | G38: 0.77430556 | H38: =IF(OR(F38="",G38=""),0,G38-F38-TIME(1,0,0)) -> 0.33402778 | I38: =IF(F38="","Absent",IF(F38>TIME(9,30,0),"Late","Present")) -> Late | J38: =IF(F38="","",IF(F38<=TIME(9,30,0),0,F38-TIME(9,30,0))) -> 0.0027777778 | K38: =IF(AND(F38<>"",G38=""),"On Duty","")
A39: EMP018 | B39: Naveen Prasad | C39: Pune | D39: Admin | E39: Admin Executive | F39: 0.3875 | G39: 0.77430556 | H39: =IF(OR(F39="",G39=""),0,G39-F39-TIME(1,0,0)) -> 0.34513889 | I39: =IF(F39="","Absent",IF(F39>TIME(9,30,0),"Late","Present")) -> Present | J39: =IF(F39="","",IF(F39<=TIME(9,30,0),0,F39-TIME(9,30,0))) -> 0 | K39: =IF(AND(F39<>"",G39=""),"On Duty","")
A40: EMP032 | B40: Nithin S | C40: Pune | D40: Admin | E40: Office Administrator | F40: 0.39166667 | H40: =IF(OR(F40="",G40=""),0,G40-F40-TIME(1,0,0)) -> 0 | I40: =IF(F40="","Absent",IF(F40>TIME(9,30,0),"Late","Present")) -> Present | J40: =IF(F40="","",IF(F40<=TIME(9,30,0),0,F40-TIME(9,30,0))) -> 0 | K40: =IF(AND(F40<>"",G40=""),"On Duty","") -> On Duty
...

Sheet MONTHLY ATTENDANCE SUMMARY
A1: MONTHLY ATTENDANCE SUMMARY
A2: Employee Number | B2: Name | C2: Department | D2: Present | E2: Absent | F2: Leave | G2: Week Off | H2: Work Hours | I2: Attendance Percentage
A3: {=_xlfn.SORTBY('EMPLOYEE MASTER DATA'!A4:B303,'EMPLOYEE MASTER DATA'!A4:A303,1)} -> EMP001 | B3: Vijay V | C3: =_xlfn.XLOOKUP('MONTHLY ATTENDANCE SUMMARY'!A3,'EMPLOYEE MASTER DATA'!A4:A303,'EMPLOYEE MASTER DATA'!D4:D303) -> Production | D3: 18 | E3: =MAX(0,24-(D3+F3)) -> 4 | F3: 2 | G3: 4 | H3: =D3*TIME(8,30,0) -> 6.375 | I3: =IF(D3+E3+F3=0,0,D3/(D3+E3+F3)) -> 0.75
A4: EMP002 | B4: Sathish V | C4: =_xlfn.XLOOKUP('MONTHLY ATTENDANCE SUMMARY'!A4,'EMPLOYEE MASTER DATA'!A5:A304,'EMPLOYEE MASTER DATA'!D5:D304) -> Production | D4: 20 | E4: =MAX(0,24-(D4+F4)) -> 2 | F4: 2 | G4: 4 | H4: =D4*TIME(8,30,0) -> 7.0833333 | I4: =IF(D4+E4+F4=0,0,D4/(D4+E4+F4)) -> 0.83333333
A5: EMP003 | B5: Aravind B | C5: =_xlfn.XLOOKUP('MONTHLY ATTENDANCE SUMMARY'!A5,'EMPLOYEE MASTER DATA'!A6:A305,'EMPLOYEE MASTER DATA'!D6:D305) -> Business Development | D5: 22 | E5: =MAX(0,24-(D5+F5)) -> 1 | F5: 1 | G5: 4 | H5: =D5*TIME(8,30,0) -> 7.7916667 | I5: =IF(D5+E5+F5=0,0,D5/(D5+E5+F5)) -> 0.91666667
A6: EMP004 | B6: Ramesh Kumar | C6: =_xlfn.XLOOKUP('MONTHLY ATTENDANCE SUMMARY'!A6,'EMPLOYEE MASTER DATA'!A7:A306,'EMPLOYEE MASTER DATA'!D7:D306) -> Front Office | D6: 22 | E6: =MAX(0,24-(D6+F6)) -> 1 | F6: 1 | G6: 4 | H6: =D6*TIME(8,30,0) -> 7.7916667 | I6: =IF(D6+E6+F6=0,0,D6/(D6+E6+F6)) -> 0.91666667
A7: EMP005 | B7: Naveen Kumar | C7: =_xlfn.XLOOKUP('MONTHLY ATTENDANCE SUMMARY'!A7,'EMPLOYEE MASTER DATA'!A8:A307,'EMPLOYEE MASTER DATA'!D8:D307) -> Front Office | D7: 18 | E7: =MAX(0,24-(D7+F7)) -> 5 | F7: 1 | G7: 4 | H7: =D7*TIME(8,30,0) -> 6.375 | I7: =IF(D7+E7+F7=0,0,D7/(D7+E7+F7)) -> 0.75
A8: EMP006 | B8: Karthik T | C8: =_xlfn.XLOOKUP('MONTHLY ATTENDANCE SUMMARY'!A8,'EMPLOYEE MASTER DATA'!A9:A308,'EMPLOYEE MASTER DATA'!D9:D308) -> Admin | D8: 18 | E8: =MAX(0,24-(D8+F8)) -> 4 | F8: 2 | G8: 4 | H8: =D8*TIME(8,30,0) -> 6.375 | I8: =IF(D8+E8+F8=0,0,D8/(D8+E8+F8)) -> 0.75
A9: EMP007 | B9: Arun B | C9: =_xlfn.XLOOKUP('MONTHLY ATTENDANCE SUMMARY'!A9,'EMPLOYEE MASTER DATA'!A10:A309,'EMPLOYEE MASTER DATA'!D10:D309) -> Admin | D9: 13 | E9: =MAX(0,24-(D9+F9)) -> 10 | F9: 1 | G9: 4 | H9: =D9*TIME(8,30,0) -> 4.6041667 | I9: =IF(D9+E9+F9=0,0,D9/(D9+E9+F9)) -> 0.54166667
A10: EMP008 | B10: Sathish G | C10: =_xlfn.XLOOKUP('MONTHLY ATTENDANCE SUMMARY'!A10,'EMPLOYEE MASTER DATA'!A11:A310,'EMPLOYEE MASTER DATA'!D11:D310) -> Accounts | D10: 18 | E10: =MAX(0,24-(D10+F10)) -> 4 | F10: 2 | G10: 4 | H10: =D10*TIME(8,30,0) -> 6.375 | I10: =IF(D10+E10+F10=0,0,D10/(D10+E10+F10)) -> 0.75
A11: EMP009 | B11: Yuvaraj Babu | C11: =_xlfn.XLOOKUP('MONTHLY ATTENDANCE SUMMARY'!A11,'EMPLOYEE MASTER DATA'!A12:A311,'EMPLOYEE MASTER DATA'!D12:D311) -> Sales | D11: 22 | E11: =MAX(0,24-(D11+F11)) -> 1 | F11: 1 | G11: 4 | H11: =D11*TIME(8,30,0) -> 7.7916667 | I11: =IF(D11+E11+F11=0,0,D11/(D11+E11+F11)) -> 0.91666667
A12: EMP010 | B12: Sanjay G | C12: =_xlfn.XLOOKUP('MONTHLY ATTENDANCE SUMMARY'!A12,'EMPLOYEE MASTER DATA'!A13:A312,'EMPLOYEE MASTER DATA'!D13:D312) -> Procurement | D12: 22 | E12: =MAX(0,24-(D12+F12)) -> 1 | F12: 1 | G12: 4 | H12: =D12*TIME(8,30,0) -> 7.7916667 | I12: =IF(D12+E12+F12=0,0,D12/(D12+E12+F12)) -> 0.91666667
A13: EMP011 | B13: Vijay T | C13: =_xlfn.XLOOKUP('MONTHLY ATTENDANCE SUMMARY'!A13,'EMPLOYEE MASTER DATA'!A14:A313,'EMPLOYEE MASTER DATA'!D14:D313) -> Accounts | D13: 21 | E13: =MAX(0,24-(D13+F13)) -> 2 | F13: 1 | G13: 4 | H13: =D13*TIME(8,30,0) -> 7.4375 | I13: =IF(D13+E13+F13=0,0,D13/(D13+E13+F13)) -> 0.875
A14: EMP012 | B14: Mohan M | C14: =_xlfn.XLOOKUP('MONTHLY ATTENDANCE SUMMARY'!A14,'EMPLOYEE MASTER DATA'!A15:A314,'EMPLOYEE MASTER DATA'!D15:D314) -> Admin | D14: 19 | E14: =MAX(0,24-(D14+F14)) -> 4 | F14: 1 | G14: 4 | H14: =D14*TIME(8,30,0) -> 6.7291667 | I14: =IF(D14+E14+F14=0,0,D14/(D14+E14+F14)) -> 0.79166667
A15: EMP013 | B15: Madhan Selvam | C15: =_xlfn.XLOOKUP('MONTHLY ATTENDANCE SUMMARY'!A15,'EMPLOYEE MASTER DATA'!A16:A315,'EMPLOYEE MASTER DATA'!D16:D315) -> Accounts | D15: 21 | E15: =MAX(0,24-(D15+F15)) -> 1 | F15: 2 | G15: 4 | H15: =D15*TIME(8,30,0) -> 7.4375 | I15: =IF(D15+E15+F15=0,0,D15/(D15+E15+F15)) -> 0.875
... A302: EMP300 | B302: Ganesh Narayanan | C302: =_xlfn.XLOOKUP('MONTHLY ATTENDANCE SUMMARY'!A302,'EMPLOYEE MASTER DATA'!A303:A602,'EMPLOYEE MASTER DATA'!D303:D602) -> Maintenance | D302: 15 | E302: =MAX(0,24-(D302+F302)) -> 7 | F302: 2 | G302: 4 | H302: =D302*TIME(8,30,0) -> 5.3125 | I302: =IF(D302+E302+F302=0,0,D302/(D302+E302+F302)) -> 0.625

Sheet PAYROLL
A1: PAYROLL
A2: Employee Details | E2: Salary Details | G2: Attendance | K2: Deductions
A3: Employee No. | B3: Name | C3: Department | D3: Designation | E3: Basic Salary | F3: Per Day Salary | G3: Present Days | H3: Approved Leaves | I3: Full Pay | J3: Half Pay | K3: Gross Salary | L3: PF | M3: Professional Tax | N3: ESI | O3: NetSalary
A4: {=_xlfn.SORTBY('EMPLOYEE MASTER DATA'!A4:B303,'EMPLOYEE MASTER DATA'!A4:A303,1)} -> EMP001 | B4: Vijay V | C4: =_xlfn.XLOOKUP(A4,'EMPLOYEE MASTER DATA'!A4:A303,'EMPLOYEE MASTER DATA'!D4:D303) -> Production | D4: =_xlfn.XLOOKUP(A4,'EMPLOYEE MASTER DATA'!A4:A303,'EMPLOYEE MASTER DATA'!E4:E303) -> Production Executive | E4: =_xlfn.XLOOKUP(A4,'EMPLOYEE MASTER DATA'!A4:A303,'EMPLOYEE MASTER DATA'!F4:F303) -> 29000 | F4: =E4/24 -> 1208.3333 | G4: {=_xlfn.XLOOKUP(PAYROLL!A4:A303,'MONTHLY ATTENDANCE SUMMARY'!A3:A302,'MONTHLY ATTENDANCE SUMMARY'!D3:D302)} -> 18 | H4: =_xlfn.XLOOKUP(A4,'MONTHLY ATTENDANCE SUMMARY'!A3:A302,'MONTHLY ATTENDANCE SUMMARY'!F3:F302) -> 2 | I4: =MIN(H4,1) -> 1 | J4: =MAX(H4-1,0) -> 1 | K4: =F4*(G4+I4+(J4*0.5)) -> 23562.5 | L4: =E4*12% -> 3480 | M4: =IF(K4>=21000,200,0) -> 200 | N4: =IF(K4<=21000,K4*0.75%,0) -> 0 | O4: =K4-SUM(L4:N4) -> 19882.5
A5: EMP002 | B5: Sathish V | C5: =_xlfn.XLOOKUP(A5,'EMPLOYEE MASTER DATA'!A5:A304,'EMPLOYEE MASTER DATA'!D5:D304) -> Production | D5: =_xlfn.XLOOKUP(A5,'EMPLOYEE MASTER DATA'!A5:A304,'EMPLOYEE MASTER DATA'!E5:E304) -> Shift Incharge | E5: =_xlfn.XLOOKUP(A5,'EMPLOYEE MASTER DATA'!A5:A304,'EMPLOYEE MASTER DATA'!F5:F304) -> 46500 | F5: =E5/24 -> 1937.5 | G5: 20 | H5: =_xlfn.XLOOKUP(A5,'MONTHLY ATTENDANCE SUMMARY'!A4:A303,'MONTHLY ATTENDANCE SUMMARY'!F4:F303) -> 2 | I5: =MIN(H5,1) -> 1 | J5: =MAX(H5-1,0) -> 1 | K5: =F5*(G5+I5+(J5*0.5)) -> 41656.25 | L5: =E5*12% -> 5580 | M5: =IF(K5>=21000,200,0) -> 200 | N5: =IF(K5<=21000,K5*0.75%,0) -> 0 | O5: =K5-SUM(L5:N5) -> 35876.25
A6: EMP003 | B6: Aravind B | C6: =_xlfn.XLOOKUP(A6,'EMPLOYEE MASTER DATA'!A6:A305,'EMPLOYEE MASTER DATA'!D6:D305) -> Business Development | D6: =_xlfn.XLOOKUP(A6,'EMPLOYEE MASTER DATA'!A6:A305,'EMPLOYEE MASTER DATA'!E6:E305) -> Senior Business Development Executive | E6: =_xlfn.XLOOKUP(A6,'EMPLOYEE MASTER DATA'!A6:A305,'EMPLOYEE MASTER DATA'!F6:F305) -> 44500 | F6: =E6/24 -> 1854.1667 | G6: 22 | H6: =_xlfn.XLOOKUP(A6,'MONTHLY ATTENDANCE SUMMARY'!A5:A304,'MONTHLY ATTENDANCE SUMMARY'!F5:F304) -> 1 | I6: =MIN(H6,1) -> 1 | J6: =MAX(H6-1,0) -> 0 | K6: =F6*(G6+I6+(J6*0.5)) -> 42645.833 | L6: =E6*12% -> 5340 | M6: =IF(K6>=21000,200,0) -> 200 | N6: =IF(K6<=21000,K6*0.75%,0) -> 0 | O6: =K6-SUM(L6:N6) -> 37105.833
A7: EMP004 | B7: Ramesh Kumar | C7: =_xlfn.XLOOKUP(A7,'EMPLOYEE MASTER DATA'!A7:A306,'EMPLOYEE MASTER DATA'!D7:D306) -> Front Office | D7: =_xlfn.XLOOKUP(A7,'EMPLOYEE MASTER DATA'!A7:A306,'EMPLOYEE MASTER DATA'!E7:E306) -> Receptionist | E7: =_xlfn.XLOOKUP(A7,'EMPLOYEE MASTER DATA'!A7:A306,'EMPLOYEE MASTER DATA'!F7:F306) -> 20500 | F7: =E7/24 -> 854.16667 | G7: 22 | H7: =_xlfn.XLOOKUP(A7,'MONTHLY ATTENDANCE SUMMARY'!A6:A305,'MONTHLY ATTENDANCE SUMMARY'!F6:F305) -> 1 | I7: =MIN(H7,1) -> 1 | J7: =MAX(H7-1,0) -> 0 | K7: =F7*(G7+I7+(J7*0.5)) -> 19645.833 | L7: =E7*12% -> 2460 | M7: =IF(K7>=21000,200,0) -> 0 | N7: =IF(K7<=21000,K7*0.75%,0) -> 147.34375 | O7: =K7-SUM(L7:N7) -> 17038.49
A8: EMP005 | B8: Naveen Kumar | C8: =_xlfn.XLOOKUP(A8,'EMPLOYEE MASTER DATA'!A8:A307,'EMPLOYEE MASTER DATA'!D8:D307) -> Front Office | D8: =_xlfn.XLOOKUP(A8,'EMPLOYEE MASTER DATA'!A8:A307,'EMPLOYEE MASTER DATA'!E8:E307) -> Front Office Executive | E8: =_xlfn.XLOOKUP(A8,'EMPLOYEE MASTER DATA'!A8:A307,'EMPLOYEE MASTER DATA'!F8:F307) -> 29000 | F8: =E8/24 -> 1208.3333 | G8: 18 | H8: =_xlfn.XLOOKUP(A8,'MONTHLY ATTENDANCE SUMMARY'!A7:A306,'MONTHLY ATTENDANCE SUMMARY'!F7:F306) -> 1 | I8: =MIN(H8,1) -> 1 | J8: =MAX(H8-1,0) -> 0 | K8: =F8*(G8+I8+(J8*0.5)) -> 22958.333 | L8: =E8*12% -> 3480 | M8: =IF(K8>=21000,200,0) -> 200 | N8: =IF(K8<=21000,K8*0.75%,0) -> 0 | O8: =K8-SUM(L8:N8) -> 19278.333
A9: EMP006 | B9: Karthik T | C9: =_xlfn.XLOOKUP(A9,'EMPLOYEE MASTER DATA'!A9:A308,'EMPLOYEE MASTER DATA'!D9:D308) -> Admin | D9: =_xlfn.XLOOKUP(A9,'EMPLOYEE MASTER DATA'!A9:A308,'EMPLOYEE MASTER DATA'!E9:E308) -> Admin Manager | E9: =_xlfn.XLOOKUP(A9,'EMPLOYEE MASTER DATA'!A9:A308,'EMPLOYEE MASTER DATA'!F9:F308) -> 53500 | F9: =E9/24 -> 2229.1667 | G9: 18 | H9: =_xlfn.XLOOKUP(A9,'MONTHLY ATTENDANCE SUMMARY'!A8:A307,'MONTHLY ATTENDANCE SUMMARY'!F8:F307) -> 2 | I9: =MIN(H9,1) -> 1 | J9: =MAX(H9-1,0) -> 1 | K9: =F9*(G9+I9+(J9*0.5)) -> 43468.75 | L9: =E9*12% -> 6420 | M9: =IF(K9>=21000,200,0) -> 200 | N9: =IF(K9<=21000,K9*0.75%,0) -> 0 | O9: =K9-SUM(L9:N9) -> 36848.75
A10: EMP007 | B10: Arun B | C10: =_xlfn.XLOOKUP(A10,'EMPLOYEE MASTER DATA'!A10:A309,'EMPLOYEE MASTER DATA'!D10:D309) -> Admin | D10: =_xlfn.XLOOKUP(A10,'EMPLOYEE MASTER DATA'!A10:A309,'EMPLOYEE MASTER DATA'!E10:E309) -> Office Coordinator | E10: =_xlfn.XLOOKUP(A10,'EMPLOYEE MASTER DATA'!A10:A309,'EMPLOYEE MASTER DATA'!F10:F309) -> 25500 | F10: =E10/24 -> 1062.5 | G10: 13 | H10: =_xlfn.XLOOKUP(A10,'MONTHLY ATTENDANCE SUMMARY'!A9:A308,'MONTHLY ATTENDANCE SUMMARY'!F9:F308) -> 1 | I10: =MIN(H10,1) -> 1 | J10: =MAX(H10-1,0) -> 0 | K10: =F10*(G10+I10+(J10*0.5)) -> 14875 | L10: =E10*12% -> 3060 | M10: =IF(K10>=21000,200,0) -> 0 | N10: =IF(K10<=21000,K10*0.75%,0) -> 111.5625 | O10: =K10-SUM(L10:N10) -> 11703.438
A11: EMP008 | B11: Sathish G | C11: =_xlfn.XLOOKUP(A11,'EMPLOYEE MASTER DATA'!A11:A310,'EMPLOYEE MASTER DATA'!D11:D310) -> Accounts | D11: =_xlfn.XLOOKUP(A11,'EMPLOYEE MASTER DATA'!A11:A310,'EMPLOYEE MASTER DATA'!E11:E310) -> Accountant | E11: =_xlfn.XLOOKUP(A11,'EMPLOYEE MASTER DATA'!A11:A310,'EMPLOYEE MASTER DATA'!F11:F310) -> 27500 | F11: =E11/24 -> 1145.8333 | G11: 18 | H11: =_xlfn.XLOOKUP(A11,'MONTHLY ATTENDANCE SUMMARY'!A10:A309,'MONTHLY ATTENDANCE SUMMARY'!F10:F309) -> 2 | I11: =MIN(H11,1) -> 1 | J11: =MAX(H11-1,0) -> 1 | K11: =F11*(G11+I11+(J11*0.5)) -> 22343.75 | L11: =E11*12% -> 3300 | M11: =IF(K11>=21000,200,0) -> 200 | N11: =IF(K11<=21000,K11*0.75%,0) -> 0 | O11: =K11-SUM(L11:N11) -> 18843.75
A12: EMP009 | B12: Yuvaraj Babu | C12: =_xlfn.XLOOKUP(A12,'EMPLOYEE MASTER DATA'!A12:A311,'EMPLOYEE MASTER DATA'!D12:D311) -> Sales | D12: =_xlfn.XLOOKUP(A12,'EMPLOYEE MASTER DATA'!A12:A311,'EMPLOYEE MASTER DATA'!E12:E311) -> Senior Sales Executive | E12: =_xlfn.XLOOKUP(A12,'EMPLOYEE MASTER DATA'!A12:A311,'EMPLOYEE MASTER DATA'!F12:F311) -> 43500 | F12: =E12/24 -> 1812.5 | G12: 22 | H12: =_xlfn.XLOOKUP(A12,'MONTHLY ATTENDANCE SUMMARY'!A11:A310,'MONTHLY ATTENDANCE SUMMARY'!F11:F310) -> 1 | I12: =MIN(H12,1) -> 1 | J12: =MAX(H12-1,0) -> 0 | K12: =F12*(G12+I12+(J12*0.5)) -> 41687.5 | L12: =E12*12% -> 5220 | M12: =IF(K12>=21000,200,0) -> 200 | N12: =IF(K12<=21000,K12*0.75%,0) -> 0 | O12: =K12-SUM(L12:N12) -> 36267.5
A13: EMP010 | B13: Sanjay G | C13: =_xlfn.XLOOKUP(A13,'EMPLOYEE MASTER DATA'!A13:A312,'EMPLOYEE MASTER DATA'!D13:D312) -> Procurement | D13: =_xlfn.XLOOKUP(A13,'EMPLOYEE MASTER DATA'!A13:A312,'EMPLOYEE MASTER DATA'!E13:E312) -> Buyer | E13: =_xlfn.XLOOKUP(A13,'EMPLOYEE MASTER DATA'!A13:A312,'EMPLOYEE MASTER DATA'!F13:F312) -> 45000 | F13: =E13/24 -> 1875 | G13: 22 | H13: =_xlfn.XLOOKUP(A13,'MONTHLY ATTENDANCE SUMMARY'!A12:A311,'MONTHLY ATTENDANCE SUMMARY'!F12:F311) -> 1 | I13: =MIN(H13,1) -> 1 | J13: =MAX(H13-1,0) -> 0 | K13: =F13*(G13+I13+(J13*0.5)) -> 43125 | L13: =E13*12% -> 5400 | M13: =IF(K13>=21000,200,0) -> 200 | N13: =IF(K13<=21000,K13*0.75%,0) -> 0 | O13: =K13-SUM(L13:N13) -> 37525
A14: EMP011 | B14: Vijay T | C14: =_xlfn.XLOOKUP(A14,'EMPLOYEE MASTER DATA'!A14:A313,'EMPLOYEE MASTER DATA'!D14:D313) -> Accounts | D14: =_xlfn.XLOOKUP(A14,'EMPLOYEE MASTER DATA'!A14:A313,'EMPLOYEE MASTER DATA'!E14:E313) -> Finance Executive | E14: =_xlfn.XLOOKUP(A14,'EMPLOYEE MASTER DATA'!A14:A313,'EMPLOYEE MASTER DATA'!F14:F313) -> 36000 | F14: =E14/24 -> 1500 | G14: 21 | H14: =_xlfn.XLOOKUP(A14,'MONTHLY ATTENDANCE SUMMARY'!A13:A312,'MONTHLY ATTENDANCE SUMMARY'!F13:F312) -> 1 | I14: =MIN(H14,1) -> 1 | J14: =MAX(H14-1,0) -> 0 | K14: =F14*(G14+I14+(J14*0.5)) -> 33000 | L14: =E14*12% -> 4320 | M14: =IF(K14>=21000,200,0) -> 200 | N14: =IF(K14<=21000,K14*0.75%,0) -> 0 | O14: =K14-SUM(L14:N14) -> 28480
A15: EMP012 | B15: Mohan M | C15: =_xlfn.XLOOKUP(A15,'EMPLOYEE MASTER DATA'!A15:A314,'EMPLOYEE MASTER DATA'!D15:D314) -> Admin | D15: =_xlfn.XLOOKUP(A15,'EMPLOYEE MASTER DATA'!A15:A314,'EMPLOYEE MASTER DATA'!E15:E314) -> Office Administrator | E15: =_xlfn.XLOOKUP(A15,'EMPLOYEE MASTER DATA'!A15:A314,'EMPLOYEE MASTER DATA'!F15:F314) -> 28000 | F15: =E15/24 -> 1166.6667 | G15: 19 | H15: =_xlfn.XLOOKUP(A15,'MONTHLY ATTENDANCE SUMMARY'!A14:A313,'MONTHLY ATTENDANCE SUMMARY'!F14:F313) -> 1 | I15: =MIN(H15,1) -> 1 | J15: =MAX(H15-1,0) -> 0 | K15: =F15*(G15+I15+(J15*0.5)) -> 23333.333 | L15: =E15*12% -> 3360 | M15: =IF(K15>=21000,200,0) -> 200 | N15: =IF(K15<=21000,K15*0.75%,0) -> 0 | O15: =K15-SUM(L15:N15) -> 19773.333
A16: EMP013 | B16: Madhan Selvam | C16: =_xlfn.XLOOKUP(A16,'EMPLOYEE MASTER DATA'!A16:A315,'EMPLOYEE MASTER DATA'!D16:D315) -> Accounts | D16: =_xlfn.XLOOKUP(A16,'EMPLOYEE MASTER DATA'!A16:A315,'EMPLOYEE MASTER DATA'!E16:E315) -> Senior Accountant | E16: =_xlfn.XLOOKUP(A16,'EMPLOYEE MASTER DATA'!A16:A315,'EMPLOYEE MASTER DATA'!F16:F315) -> 40500 | F16: =E16/24 -> 1687.5 | G16: 21 | H16: =_xlfn.XLOOKUP(A16,'MONTHLY ATTENDANCE SUMMARY'!A15:A314,'MONTHLY ATTENDANCE SUMMARY'!F15:F314) -> 2 | I16: =MIN(H16,1) -> 1 | J16: =MAX(H16-1,0) -> 1 | K16: =F16*(G16+I16+(J16*0.5)) -> 37968.75 | L16: =E16*12% -> 4860 | M16: =IF(K16>=21000,200,0) -> 200 | N16: =IF(K16<=21000,K16*0.75%,0) -> 0 | O16: =K16-SUM(L16:N16) -> 32908.75
... A303: EMP300 | B303: Ganesh Narayanan | C303: =_xlfn.XLOOKUP(A303,'EMPLOYEE MASTER DATA'!A303:A602,'EMPLOYEE MASTER DATA'!D303:D602) -> Maintenance | D303: =_xlfn.XLOOKUP(A303,'EMPLOYEE MASTER DATA'!A303:A602,'EMPLOYEE MASTER DATA'!E303:E602) -> Maintenance Supervisor | E303: =_xlfn.XLOOKUP(A303,'EMPLOYEE MASTER DATA'!A303:A602,'EMPLOYEE MASTER DATA'!F303:F602) -> 42000 | F303: =E303/24 -> 1750 | G303: 15 | H303: =_xlfn.XLOOKUP(A303,'MONTHLY ATTENDANCE SUMMARY'!A302:A601,'MONTHLY ATTENDANCE SUMMARY'!F302:F601) -> 2 | I303: =MIN(H303,1) -> 1 | J303: =MAX(H303-1,0) -> 1 | K303: =F303*(G303+I303+(J303*0.5)) -> 28875 | L303: =E303*12% -> 5040 | M303: =IF(K303>=21000,200,0) -> 200 | N303: =IF(K303<=21000,K303*0.75%,0) -> 0 | O303: =K303-SUM(L303:N303) -> 23635

Sheet SALARY SLIP
A1: NOVATECH SOLUTIONS PVT. LTD.
A3: SALARY SLIP - FEBRUARY 2026
A5: Employee ID | C5: EMP100
A6: Employee Name | C6: =_xlfn.XLOOKUP('SALARY SLIP'!C5,'MONTHLY ATTENDANCE SUMMARY'!A3:A302,'MONTHLY ATTENDANCE SUMMARY'!B3:B302," ") -> Deepak K
A7: Department | C7: =_xlfn.XLOOKUP('SALARY SLIP'!C5,'MONTHLY ATTENDANCE SUMMARY'!A3:A302,'MONTHLY ATTENDANCE SUMMARY'!C3:C302," ") -> Business Development
A8: Designation | C8: =_xlfn.XLOOKUP('SALARY SLIP'!C5,'EMPLOYEE MASTER DATA'!A4:A303,'EMPLOYEE MASTER DATA'!E4:E303," ") -> Growth Executive
A10: ATTENDANCE
A11: Present Days | C11: {=_xlfn.XLOOKUP(C5,PAYROLL!A4:A303,_xlfn.ANCHORARRAY(PAYROLL!G4)," ")} -> 20
A12: Approved Leave | C12: =_xlfn.XLOOKUP(C5,PAYROLL!A4:A303,PAYROLL!H4:H303," ") -> 1
A14: EARNINGS
A15: Basic Salary | F15: =_xlfn.XLOOKUP(C5,PAYROLL!A4:A303,PAYROLL!E4:E303," ") -> 44500
A16: Gross Salary | F16: =_xlfn.XLOOKUP(C5,PAYROLL!A4:A303,PAYROLL!K4:K303," ") -> 38937.5
A18: DEDUCTIONS
A19: PF | F19: =_xlfn.XLOOKUP('SALARY SLIP'!C5,PAYROLL!A4:A303,PAYROLL!L4:L303) -> 5340
A20: Professional Tax | F20: =_xlfn.XLOOKUP(C5,PAYROLL!A4:A303,PAYROLL!M4:M303,"-") -> 200
A21: ESI | F21: =_xlfn.XLOOKUP(C5,PAYROLL!A4:A303,PAYROLL!N4:N303,"-") -> 0
A23: Net Salary | F23: =_xlfn.XLOOKUP(C5,PAYROLL!A4:A303,PAYROLL!O4:O303) -> 33397.5
A24: This is a computer-generated salary slip.

Sheet PIVOTS
A1: DEPARTMENT - WISE EMPLOYEES | D1: DEPARTMENT - WISE GROSS SALARY
A2: Row Labels | B2: Count of Emp No | D2: Row Labels | E2: Sum of Gross Salary
A3: Accounts | B3: 32 | D3: Accounts | E3: 1318895.8
A4: Admin | B4: 26 | D4: Admin | E4: 685739.58
A5: Back End | B5: 22 | D5: Back End | E5: 667739.58
A6: Business Development | B6: 25 | D6: Business Development | E6: 1013500
A7: Customer Relationship | B7: 21 | D7: Customer Relationship | E7: 575104.17
A8: Front Office | B8: 22 | D8: Front Office | E8: 546937.5
A9: HR | B9: 16 | D9: HR | E9: 571093.75
A10: IT | B10: 19 | D10: IT | E10: 903697.92
A11: Maintenance | B11: 36 | D11: Maintenance | E11: 1546385.4
A12: Procurement | B12: 19 | D12: Procurement | E12: 742958.33
A13: Production | B13: 33 | D13: Production | E13: 1377614.6
A14: Sales | B14: 29 | D14: Sales | E14: 1067885.4
A15: Grand Total | B15: 300 | D15: Grand Total | E15: 11017552
A17: TOP 10 HIGHEST PAID EMPLOYEES | D17: ATTENDANCE DISTRIBUTION
A18: Name | B18: Sum of Gross Salary | D18: Status | E18: Percentage
A19: Vijay Babu | B19: 72656.25 | D19: Present | E19: ='HR MIS DASHBOARD'!D5 -> 0.83152778
A20: Ajay V | B20: 72875 | D20: Absent | E20: ='HR MIS DASHBOARD'!G5 -> 0.092274678
A21: Arun T | B21: 72947.917 | D21: Leave | E21: ='HR MIS DASHBOARD'!J5 -> 0.036712272
A22: Vignesh V | B22: 75708.333 | D22: Week Off | E22: =1-SUM(E19:E21) -> 0.039485272
A23: Aravind S | B23: 77083.333
A24: Sanjay Babu | B24: 79218.75
A25: Yogesh M | B25: 83854.167
A26: Bharath Kannan | B26: 83906.25
A27: Suresh Raj | B27: 88125
A28: Mohan K | B28: 88166.667

Sheet HR MIS DASHBOARD
A1: NOVATECH SOLUTIONS PVT. LTD.
A2: HR MIS DASHBOARD - FEBRUARY 2026
A3: TOTAL EMPLOYEES | D3: PRESENT PERCENTAGE | G3: ABSENT PERCETNAGE | J3: LEAVE PERCENTAGE
A5: =COUNTA('EMPLOYEE MASTER DATA'!A4:A303) -> 300 | D5: =AVERAGE('MONTHLY ATTENDANCE SUMMARY'!I3:I302) -> 0.83152778 | G5: =SUM('MONTHLY ATTENDANCE SUMMARY'!E3:E302)/(SUM('MONTHLY ATTENDANCE SUMMARY'!D3:D302)+SUM('MONTHLY ATTENDANCE SUMMARY'!E3:E302)+SUM('MONTHLY ATTENDANCE SUMMARY'!F3:F302)+SUM('MONTHLY ATTENDANCE SUMMARY'!G6:G302)) -> 0.092274678 | J5: =SUM('MONTHLY ATTENDANCE SUMMARY'!F3:F302)/(SUM('MONTHLY ATTENDANCE SUMMARY'!D3:D302)+SUM('MONTHLY ATTENDANCE SUMMARY'!E3:E302)+SUM('MONTHLY ATTENDANCE SUMMARY'!F3:IF302)+SUM('MONTHLY ATTENDANCE SUMMARY'!G6:G302)) -> 0.036712272
A7: GROSS PAYROLL | D7: NET PAYROLL | G7: AVG. GROSS SALARY | J7: PF TOTAL
A9: =SUM(PAYROLL!K4:K303) -> 11017552 | D9: =SUM(PAYROLL!O4:O303) -> 9460739.8 | G9: =AVERAGE(PAYROLL!K4:K303) -> 36725.174 | J9: =SUM(PAYROLL!L4:L303) -> 1497780

Sheet READ ME
B2: HR MIS DASHBOARD PROJECT
B4: Project Objective
B5: This project was developed to monitor and analyze HR data using Microsoft Excel. It provides insights into employee attendance, payroll, salary, and departmental statistics through an interactive dashboard.
B9: Key Features
B10: Total Employees KPI
B11: Present Percentage
B12: Absent Percentage
B13: Leave Percentage
B14: Gross Payroll
B15: Net Payroll
B16: Average Gross Salary
B17: PF Total
... B90: YUWARAJA G
